# Generated by Django 3.2.23 on 2024-04-03 05:00

from django.conf import settings
import django.contrib.auth.validators
from django.db import migrations, models
import django.db.models.deletion


class Migration(migrations.Migration):

    dependencies = [
        ('users', '0015_auto_20240401_1735'),
    ]

    operations = [
        migrations.AddField(
            model_name='customer',
            name='image',
            field=models.ImageField(blank=True, null=True, upload_to='customers/profile_images/'),
        ),
        migrations.AddField(
            model_name='customer',
            name='user',
            field=models.ForeignKey(blank=True, null=True, on_delete=django.db.models.deletion.CASCADE, to=settings.AUTH_USER_MODEL),
        ),
        migrations.AlterField(
            model_name='user',
            name='username',
            field=models.CharField(default='76d93f905f2d4d39aa00b869a088208c', error_messages={'unique': 'A user with that username already exists.'}, help_text='Required. 150 characters or fewer. Letters, digits and @/./+/-/_ only.', max_length=150, unique=True, validators=[django.contrib.auth.validators.UnicodeUsernameValidator()], verbose_name='username'),
        ),
    ]
